Workbook

Sheet Part type
A1: Part number | B1: 129-122-03-211
A3: Součet z 1 | B3: Součet z 1.I | C3: Součet z 1.II | D3: Součet z 1.III | E3: Součet z 2 | F3: Součet z 22 | G3: Součet z 23 | H3: Součet z 24 | I3: Součet z 3 | J3: Součet z 32 | K3: Součet z 33 | L3: Součet z 34 | M3: Součet z 4 | N3: Součet z 42 | O3: Součet z 43 | P3: Součet z 44 | Q3: Součet z 5 | R3: Součet z 52 | S3: Součet z 53 | T3: Součet z 54 | U3: Součet z 6 | V3: Součet z 62 | W3: Součet z 63 | X3: Součet z 64 | Y3: Součet z 7 | Z3: Součet z 72 | AA3: Součet z 73 | AB3: Součet z 74 | AC3: Součet z 8 | AD3: Součet z 82 | AE3: Součet z 83 | AF3: Součet z 84 | AG3: Součet z 9 | AH3: Součet z 92 | AI3: Součet z 93 | AJ3: Součet z 94 | AK3: Součet z 10 | AL3: Součet z 102 | AM3: Součet z 103 | AN3: Součet z 104 | AO3: Součet z 11 | AP3: Součet z 112 | AQ3: Součet z 113 | AR3: Součet z 114 | AS3: Součet z 12 | AT3: Součet z 122 | AU3: Součet z 123 | AV3: Součet z 124 | AW3: Součet z 13 | AX3: Součet z 132 | AY3: Součet z 133 | AZ3: Součet z 134 | BA3: Součet z 14 | BB3: Součet z 142 | BC3: Součet z 143 | BD3: Součet z 144 | BE3: Součet z 15 | BF3: Součet z 152 | BG3: Součet z 153 | BH3: Součet z 154 | BI3: Součet z 16 | BJ3: Součet z 162 | BK3: Součet z 163 | BL3: Součet z 164 | BM3: Součet z 17 | BN3: Součet z 172 | BO3: Součet z 173 | BP3: Součet z 174
A4: -15.172222 | B4: -14.716586 | C4: -14.633744 | D4: -14.550901 | E4: 392.34308 | F4: 391.43184 | G4: 391.26616 | H4: 391.10048 | I4: 33.52846 | J4: 32.88408 | K4: 32.76692 | L4: 32.64976 | M4: 207.55361 | N4: 206.66393 | O4: 206.50217 | P4: 206.34041 | Q4: 33.4162 | R4: 32.78194 | S4: 32.66662 | T4: 32.5513 | U4: -31.24288 | V4: -30.64987 | W4: -30.54205 | X4: -30.43423 | Y4: -392.2926 | Z4: -391.38301 | AA4: -391.21763 | AB4: -391.05225 | AC4: 26.40155 | AD4: 26.34039 | AE4: 26.32927 | AF4: 26.31815 | AG4: -35.86938 | AH4: -35.17187 | AI4: -35.04505 | AJ4: -34.91823 | AK4: -33.53845 | AL4: -32.88626 | AM4: -32.76768 | AN4: -32.6491 | AO4: -233.83777 | AP4: -232.90475 | AQ4: -232.73511 | AR4: -232.56547 | AS4: 0 | AT4: 0 | AU4: 0 | AV4: 0 | AW4: 33.52846 | AX4: 32.88408 | AY4: 32.76692 | AZ4: 32.64976 | BA4: -33.52846 | BB4: -32.88408 | BC4: -32.76692 | BD4: -32.64976 | BE4: 33.52846 | BF4: 32.88408 | BG4: 32.76692 | BH4: 32.64976 | BI4: 0 | BJ4: 0 | BK4: 0 | BL4: 0 | BM4: 0 | BN4: 0 | BO4: 0 | BP4: 0
B8: TOOL DIAMETER - REAL MEASURED (MM) | C8: 94.4 | D8: /2 = | E8: =C8/2 -> 47.2 | F8: (TOOL RADIUS) | J8: =E8+1.5 -> 48.7 | K8: (FIRST TAKE) | N8: =-(J8+(C14/2)) -> -48.7 | O8: (START POSITION "Y/1")
B9: WIDTH OF TOOL - REAL MEASURED (MM) | C9: 24.3 | D9: ((C3-C6)/2)+C6= | E9: =((C9-C12)/2)+C12 -> 21.65 | F9: (TOOL DEEP FOR WORK) | J9: =E8+0.4 -> 47.6 | K9: (SECOND TAKE) | N9: =-(J9+(C14/2)) -> -47.6 | O9: (START POSITION "Y/2")
B10: WORK COORDINATE SYSTEM | C10: G58 | J10: =E8+0.2 -> 47.4 | K10: (THIRD TAKE) | N10: =-(J10+(C14/2)) -> -47.4 | O10: (START POSITION "Y/3")
B11: PART NAME/NUMBER - FROM THE DRAWING | C11: ='Part type'!B7 -> 0 | J11: =E8 -> 47.2 | K11: (FOURTH TAKE) | N11: =-(J11+(C14/2)) -> -47.2 | O11: (START POSITION "Y/4")
B12: REAL THICKNESS OF THE PART -THK (MM) | C12: 19
B13: CORRECTION OF DIMENSIONS IN THE "X" AXIS | C13: 0 | D13: /2 = | E13: =C13/2 -> 0
B14: CORRECTION OF DIMENSIONS IN THE "Y" AXIS | C14: 0
B15: FEED FOR ROUGHING (MM/MIN) | C15: 1000
B16: FEED FOR FINISHING (MM/MIN) | C16: 2000

Sheet Part program
A1: =_xlfn.CONCAT(E1:N1) -> % | E1: %
A2: =_xlfn.CONCAT(D2:N2) -> O0001 | E2: O0001
A3: =_xlfn.CONCAT(D3:N3) -> (PART NAME/NUMBER:129-122-03-211/ THK 19MM/PERIMETER) | E3: (PART NAME/NUMBER: | F3: ='Part type'!B1 -> 129-122-03-211 | G3: / THK | H3: ='Part type'!C12 -> 19 | I3: MM/ | J3: PERIMETER)
A4: =_xlfn.CONCAT(D4:N4) -> (TOOL:ØX94,4MM/THK24,3MM) | E4: (TOOL: | F4: Ø | H4: X | I4: ='Part type'!C8 -> 94.4 | J4: MM/ | K4: THK | L4: ='Part type'!C9 -> 24.3 | M4: MM)
A5: =_xlfn.CONCAT(D5:N5) -> S5500M03 | E5: S | F5: =IF(I4<110,5500,3800) -> 5500 | G5: M03
A6: =_xlfn.CONCAT(D6:N6) -> G90G40G49G80G98 | E6: G90 | F6: G40 | G6: G49 | H6: G80 | I6: G98
A7: =_xlfn.CONCAT(D7:N7) -> G21G00G58G17 | E7: G21 | F7: G00 | G7: ='Part type'!C10 -> G58 | H7: G17
A8: =_xlfn.CONCAT(D8:N8) -> T01M06 | E8: T01 | F8: M06
A9: =_xlfn.CONCAT(D9:N9) -> G90G00G43Z50,0H01 | E9: G90 | F9: G00 | G9: G43 | K9: Z | L9: 50,0 | M9: H | N9: 01
A10: =_xlfn.CONCAT(D10:N10) -> G90G00X-47,2Y-57,2 | E10: G90 | F10: G00 | G10: X | H10: =-('Part type'!E8) -> -47.2 | I10: Y | J10: =-('Part type'!E8+10) -> -57.2
A11: =_xlfn.CONCAT(D11:N11) -> Z10,0 | K11: Z | L11: 10,0
A12: =_xlfn.CONCAT(D12:N12) -> G01Z-21,65F3000 | F12: G01 | K12: Z | L12: =-('Part type'!E9) -> -21.65 | M12: F | N12: 3000
A13: =_xlfn.CONCAT(D13:N13)
A14: =_xlfn.CONCAT(D14:N14) -> G01X-47,2Y-48,7F1000 | F14: G01 | G14: X | H14: =-('Part type'!E8) -> -47.2 | I14: Y | J14: ='Part type'!N8 -> -48.7 | M14: F | N14: ='Part type'!C15 -> 1000
A15: =_xlfn.CONCAT(D15:N15)
A16: =_xlfn.CONCAT(D16:N16) -> G90G01X-15,1722218Y-48,7Z-21,65 | E16: G90 | F16: G01 | G16: X | H16: ='Part type'!A4 -> -15.172222 | I16: Y | J16: ='Part type'!N8 -> -48.7 | K16: Z | L16: =-('Part type'!E9) -> -21.65
A17: =_xlfn.CONCAT(D17:N17) -> G91G01X392,34308Y0Z0,3 | E17: G91 | F17: G01 | G17: X | H17: ='Part type'!E4 -> 392.34308 | I17: Y | J17: ='Part type'!BM4 -> 0 | K17: Z | L17: 0.3
A18: =_xlfn.CONCAT(D18:N18) -> X33,52846Y33,52846 | G18: X | H18: ='Part type'!I4 -> 33.52846 | I18: Y | J18: ='Part type'!AW4 -> 33.52846
A19: =_xlfn.CONCAT(D19:N19) -> X0Y207,55361 | G19: X | H19: ='Part type'!AS4 -> 0 | I19: Y | J19: ='Part type'!M4 -> 207.55361
A20: =_xlfn.CONCAT(D20:N20) -> X-31,24288Y33,4162 | G20: X | H20: ='Part type'!U4 -> -31.24288 | I20: Y | J20: ='Part type'!Q4 -> 33.4162
A21: =_xlfn.CONCAT(D21:N21) -> X-392,2926Y26,40155Z-0,3 | G21: X | H21: ='Part type'!Y4 -> -392.2926 | I21: Y | J21: ='Part type'!AC4 -> 26.40155 | K21: Z | L21: -0.3
A22: =_xlfn.CONCAT(D22:N22) -> X-35,86938Y-33,53845 | G22: X | H22: ='Part type'!AG4 -> -35.86938 | I22: Y | J22: ='Part type'!AK4 -> -33.53845
A23: =_xlfn.CONCAT(D23:N23) -> X0Y-233,83777 | G23: X | H23: ='Part type'!BI4 -> 0 | I23: Y | J23: ='Part type'!AO4 -> -233.83777
A24: =_xlfn.CONCAT(D24:N24) -> X33,52846Y-33,52846 | G24: X | H24: ='Part type'!BE4 -> 33.52846 | I24: Y | J24: ='Part type'!BA4 -> -33.52846
A25: =_xlfn.CONCAT(D25:N25)
A26: =_xlfn.CONCAT(D26:N26) -> G90G01X-14,7165864Y-47,6Z-21,65F1000 | E26: G90 | F26: G01 | G26: X | H26: ='Part type'!B4 -> -14.716586 | I26: Y | J26: ='Part type'!N9 -> -47.6 | K26: Z | L26: =-('Part type'!E9) -> -21.65 | M26: F | N26: ='Part type'!C15 -> 1000
A27: =_xlfn.CONCAT(D27:N27) -> G91G01X391,43184Y0Z0,3 | E27: G91 | F27: G01 | G27: X | H27: ='Part type'!F4 -> 391.43184 | I27: Y | J27: ='Part type'!BN4 -> 0 | K27: Z | L27: 0.3
A28: =_xlfn.CONCAT(D28:N28) -> X32,88408Y32,88408 | G28: X | H28: ='Part type'!J4 -> 32.88408 | I28: Y | J28: ='Part type'!AX4 -> 32.88408
A29: =_xlfn.CONCAT(D29:N29) -> X0Y206,66393 | G29: X | H29: ='Part type'!AT4 -> 0 | I29: Y | J29: ='Part type'!N4 -> 206.66393
A30: =_xlfn.CONCAT(D30:N30) -> X-30,64987Y32,78194 | G30: X | H30: ='Part type'!V4 -> -30.64987 | I30: Y | J30: ='Part type'!R4 -> 32.78194
A31: =_xlfn.CONCAT(D31:N31) -> X-391,38301Y26,34039Z-0,3 | G31: X | H31: ='Part type'!Z4 -> -391.38301 | I31: Y | J31: ='Part type'!AD4 -> 26.34039 | K31: Z | L31: -0.3
A32: =_xlfn.CONCAT(D32:N32) -> X-35,17187Y-32,88626 | G32: X | H32: ='Part type'!AH4 -> -35.17187 | I32: Y | J32: ='Part type'!AL4 -> -32.88626
A33: =_xlfn.CONCAT(D33:N33) -> X0Y-232,90475 | G33: X | H33: ='Part type'!BJ4 -> 0 | I33: Y | J33: ='Part type'!AP4 -> -232.90475
A34: =_xlfn.CONCAT(D34:N34) -> X32,88408Y-32,88408 | G34: X | H34: ='Part type'!BF4 -> 32.88408 | I34: Y | J34: ='Part type'!BB4 -> -32.88408
A35: =_xlfn.CONCAT(D35:N35)
A36: =_xlfn.CONCAT(D36:N36) -> G90G01X-14,6337436Y-47,4Z-21,65F2000 | E36: G90 | F36: G01 | G36: X | H36: ='Part type'!C4 -> -14.633744 | I36: Y | J36: ='Part type'!N10 -> -47.4 | K36: Z | L36: =-('Part type'!E9) -> -21.65 | M36: F | N36: ='Part type'!C16 -> 2000
A37: =_xlfn.CONCAT(D37:N37) -> G91G01X391,26616Y0Z0,3 | E37: G91 | F37: G01 | G37: X | H37: ='Part type'!G4 -> 391.26616 | I37: Y | J37: ='Part type'!BO4 -> 0 | K37: Z | L37: 0.3
A38: =_xlfn.CONCAT(D38:N38) -> X32,76692Y32,76692 | G38: X | H38: ='Part type'!K4 -> 32.76692 | I38: Y | J38: ='Part type'!AY4 -> 32.76692
A39: =_xlfn.CONCAT(D39:N39) -> X0Y206,50217 | G39: X | H39: ='Part type'!AU4 -> 0 | I39: Y | J39: ='Part type'!O4 -> 206.50217
A40: =_xlfn.CONCAT(D40:N40) -> X-30,54205Y32,66662 | G40: X | H40: ='Part type'!W4 -> -30.54205 | I40: Y | J40: ='Part type'!S4 -> 32.66662
...

Sheet Part drawings

Sheet All parts parameters
B1: Cut - 1 | C1: Cut - 2 | D1: Cut - 3 | E1: Cut - 4 | F1: Cut - 1 | G1: Cut - 2 | H1: Cut - 3 | I1: Cut - 4 | J1: Cut - 1 | K1: Cut - 2 | L1: Cut - 3 | M1: Cut - 4 | N1: Cut - 1 | O1: Cut - 2 | P1: Cut - 3 | Q1: Cut - 4 | R1: Cut - 1 | S1: Cut - 2 | T1: Cut - 3 | U1: Cut - 4 | V1: Cut - 1 | W1: Cut - 2 | X1: Cut - 3 | Y1: Cut - 4 | Z1: Cut - 1 | AA1: Cut - 2 | AB1: Cut - 3 | AC1: Cut - 4 | AD1: Cut - 1 | AE1: Cut - 2 | AF1: Cut - 3 | AG1: Cut - 4 | AH1: Cut - 1 | AI1: Cut - 2 | AJ1: Cut - 3 | AK1: Cut - 4 | AL1: Cut - 1 | AM1: Cut - 2 | AN1: Cut - 3 | AO1: Cut - 4 | AP1: Cut - 1 | AQ1: Cut - 2 | AR1: Cut - 3 | AS1: Cut - 4 | AT1: Cut - 1 | AU1: Cut - 2 | AV1: Cut - 3 | AW1: Cut - 4 | AX1: Cut - 1 | AY1: Cut - 2 | AZ1: Cut - 3 | BA1: Cut - 4 | BB1: Cut - 1 | BC1: Cut - 2 | BD1: Cut - 3 | BE1: Cut - 4 | BF1: Cut - 1 | BG1: Cut - 2 | BH1: Cut - 3 | BI1: Cut - 4 | BJ1: Cut - 1 | BK1: Cut - 2 | BL1: Cut - 3 | BM1: Cut - 4 | BN1: Cut - 1 | BO1: Cut - 2 | BP1: Cut - 3 | BQ1: Cut - 4
A2: Part number | B2: 1 | C2: 1.I | D2: 1.II | E2: 1.III | F2: 2 | G2: 22 | H2: 23 | I2: 24 | J2: 3 | K2: 32 | L2: 33 | M2: 34 | N2: 4 | O2: 42 | P2: 43 | Q2: 44 | R2: 5 | S2: 52 | T2: 53 | U2: 54 | V2: 6 | W2: 62 | X2: 63 | Y2: 64 | Z2: 7 | AA2: 72 | AB2: 73 | AC2: 74 | AD2: 8 | AE2: 82 | AF2: 83 | AG2: 84 | AH2: 9 | AI2: 92 | AJ2: 93 | AK2: 94 | AL2: 10 | AM2: 102 | AN2: 103 | AO2: 104 | AP2: 11 | AQ2: 112 | AR2: 113 | AS2: 114 | AT2: 12 | AU2: 122 | AV2: 123 | AW2: 124 | AX2: 13 | AY2: 132 | AZ2: 133 | BA2: 134 | BB2: 14 | BC2: 142 | BD2: 143 | BE2: 144 | BF2: 15 | BG2: 152 | BH2: 153 | BI2: 154 | BJ2: 16 | BK2: 162 | BL2: 163 | BM2: 164 | BN2: 17 | BO2: 172 | BP2: 173 | BQ2: 174
A3: 129-122-03-210 | B3: =-((('Part type'!J8)*0.414214)-5) -> -15.172222 | C3: =-((('Part type'!J9)*0.414214)-5) -> -14.716586 | D3: =-((('Part type'!J10)*0.414214)-5) -> -14.633744 | E3: =-((('Part type'!J11)*0.414214)-5) -> -14.550901 | F3: =(0.08284*(('Part type'!J8)*10)+352+('Part type'!E13)) -> 392.34308 | G3: =(0.08284*(('Part type'!J9)*10)+352+('Part type'!E13)) -> 391.43184 | H3: =(0.08284*(('Part type'!J10)*10)+352+('Part type'!E13)) -> 391.26616 | I3: =(0.08284*(('Part type'!J11)*10)+352+('Part type'!E13)) -> 391.10048 | J3: =(0.05858*(('Part type'!J8)*10)+5) -> 33.52846 | K3: =(0.05858*(('Part type'!J9)*10)+5) -> 32.88408 | L3: =(0.05858*(('Part type'!J10)*10)+5) -> 32.76692 | M3: =(0.05858*(('Part type'!J11)*10)+5) -> 32.64976 | N3: =(0.0791*(('Part type'!J8)*10)+108.12179+('Part type'!C14)) -> 146.64349 | O3: =(0.0791*(('Part type'!J9)*10)+108.12179+('Part type'!C14)) -> 145.77339 | P3: =(0.0791*(('Part type'!J10)*10)+108.12179+('Part type'!C14)) -> 145.61519 | Q3: =(0.0791*(('Part type'!J11)*10)+108.12179+('Part type'!C14)) -> 145.45699 | R3: =(0.05662*(('Part type'!J8)*10)+5.64571) -> 33.21965 | S3: =(0.05662*(('Part type'!J9)*10)+5.64571) -> 32.59683 | T3: =(0.05662*(('Part type'!J10)*10)+5.64571) -> 32.48359 | U3: =(0.05662*(('Part type'!J11)*10)+5.64571) -> 32.37035 | V3: =-(0.04972*(('Part type'!J8)*10)+4.95813) -> -29.17177 | W3: =-(0.04972*(('Part type'!J9)*10)+4.95813) -> -28.62485 | X3: =-(0.04972*(('Part type'!J10)*10)+4.95813) -> -28.52541 | Y3: =-(0.04972*(('Part type'!J11)*10)+4.95813) -> -28.42597 | Z3: =-(0.08226*(('Part type'!J8)*10)+352.08373+('Part type'!C13)) -> -392.14435 | AA3: =-(0.08226*(('Part type'!J9)*10)+352.08373+('Part type'!C13)) -> -391.23949 | AB3: =-(0.08226*(('Part type'!J10)*10)+352.08373+('Part type'!C13)) -> -391.07497 | AC3: =-(0.08226*(('Part type'!J11)*10)+352.08373+('Part type'!C13)) -> -390.91045 | AD3: =(0.01071*(('Part type'!J8)*10)+45.85267) -> 51.06844 | AE3: =(0.01071*(('Part type'!J9)*10)+45.85267) -> 50.95063 | AF3: =(0.01071*(('Part type'!J10)*10)+45.85267) -> 50.92921 | AG3: =(0.01071*(('Part type'!J11)*10)+45.85267) -> 50.90779 | AH3: =-(0.06803*(('Part type'!J8)*10)+4.95813) -> -38.08874 | AI3: =-(0.06803*(('Part type'!J9)*10)+4.95813) -> -37.34041 | AJ3: =-(0.06803*(('Part type'!J10)*10)+4.95813) -> -37.20435 | AK3: =-(0.06803*(('Part type'!J11)*10)+4.95813) -> -37.06829 | AL3: =-(0.05974*(('Part type'!J8)*10)+4.35429) -> -33.44767 | AM3: =-(0.05974*(('Part type'!J9)*10)+4.35429) -> -32.79053 | AN3: =-(0.05974*(('Part type'!J10)*10)+4.35429) -> -32.67105 | AO3: =-(0.05974*(('Part type'!J11)*10)+4.35429) -> -32.55157 | AP3: =-(0.08669*(('Part type'!J8)*10)+155.26588+('Part type'!C14)) -> -197.48391 | AQ3: =-(0.08669*(('Part type'!J9)*10)+155.26588+('Part type'!C14)) -> -196.53032 | AR3: =-(0.08669*(('Part type'!J10)*10)+155.26588+('Part type'!C14)) -> -196.35694 | AS3: =-(0.08669*(('Part type'!J11)*10)+155.26588+('Part type'!C14)) -> -196.18356 | AT3: 0 | AU3: 0 | AV3: 0 | AW3: 0 | AX3: =(0.05858*(('Part type'!J8)*10)+5) -> 33.52846 | AY3: =(0.05858*(('Part type'!J9)*10)+5) -> 32.88408 | AZ3: =(0.05858*(('Part type'!J10)*10)+5) -> 32.76692 | BA3: =(0.05858*(('Part type'!J11)*10)+5) -> 32.64976 | BB3: =-(0.05858*(('Part type'!J8)*10)+5) -> -33.52846 | BC3: =-(0.05858*(('Part type'!J9)*10)+5) -> -32.88408 | BD3: =-(0.05858*(('Part type'!J10)*10)+5) -> -32.76692 | BE3: =-(0.05858*(('Part type'!J11)*10)+5) -> -32.64976 | BF3: =(0.05858*(('Part type'!J8)*10)+5) -> 33.52846 | BG3: =(0.05858*(('Part type'!J9)*10)+5) -> 32.88408 | BH3: =(0.05858*(('Part type'!J10)*10)+5) -> 32.76692 | BI3: =(0.05858*(('Part type'!J11)*10)+5) -> 32.64976 | BJ3: 0 | BK3: 0 | BL3: 0 | BM3: 0 | BN3: 0 | BO3: 0 | BP3: 0 | BQ3: 0
A5: 129-122-03-102 | B5: =-((('Part type'!J8)*0.414214)-5) -> -15.172222 | C5: =-((('Part type'!J9)*0.414214)-5) -> -14.716586 | D5: =-((('Part type'!J10)*0.414214)-5) -> -14.633744 | E5: =-((('Part type'!J11)*0.414214)-5) -> -14.550901 | F5: =(0.08793*(('Part type'!J8)*10)+386.41309+('Part type'!E13)) -> 429.235 | G5: =(0.08793*(('Part type'!J9)*10)+386.41309+('Part type'!E13)) -> 428.26777 | H5: =(0.08793*(('Part type'!J10)*10)+386.41309+('Part type'!E13)) -> 428.09191 | I5: =(0.08793*(('Part type'!J11)*10)+386.41309+('Part type'!E13)) -> 427.91605 | J5: =(0.05994*(('Part type'!J8)*10)+4.15153) -> 33.34231 | K5: =(0.05994*(('Part type'!J9)*10)+4.15153) -> 32.68297 | L5: =(0.05994*(('Part type'!J10)*10)+4.15153) -> 32.56309 | M5: =(0.05994*(('Part type'!J11)*10)+4.15153) -> 32.44321 | N5: =(0.07844*(('Part type'!J8)*10)+231.7593+('Part type'!C14)) -> 269.95958 | O5: =(0.07844*(('Part type'!J9)*10)+231.7593+('Part type'!C14)) -> 269.09674 | P5: =(0.07844*(('Part type'!J10)*10)+231.7593+('Part type'!C14)) -> 268.93986 | Q5: =(0.07844*(('Part type'!J11)*10)+231.7593+('Part type'!C14)) -> 268.78298 | R5: =(0.04565*(('Part type'!J8)*10)+5.5367) -> 27.76825 | S5: =(0.04565*(('Part type'!J9)*10)+5.5367) -> 27.2661 | T5: =(0.04565*(('Part type'!J10)*10)+5.5367) -> 27.1748 | U5: =(0.04565*(('Part type'!J11)*10)+5.5367) -> 27.0835 | V5: =-(0.04791*(('Part type'!J8)*10)+5.81121) -> -29.14338 | W5: =-(0.04791*(('Part type'!J9)*10)+5.81121) -> -28.61637 | X5: =-(0.04791*(('Part type'!J10)*10)+5.81121) -> -28.52055 | Y5: =-(0.04791*(('Part type'!J11)*10)+5.81121) -> -28.42473 | Z5: =-(0.07755*(('Part type'!J8)*10)+344.88384+('Part type'!C13)) -> -382.65069 | AA5: =-(0.07755*(('Part type'!J9)*10)+344.88384+('Part type'!C13)) -> -381.79764 | AB5: =-(0.07755*(('Part type'!J10)*10)+344.88384+('Part type'!C13)) -> -381.64254 | AC5: =-(0.07755*(('Part type'!J11)*10)+344.88384+('Part type'!C13)) -> -381.48744 | AD5: =(0.00952*(('Part type'!J8)*10)+42.33704) -> 46.97328 | AE5: =(0.00952*(('Part type'!J9)*10)+42.33704) -> 46.86856 | AF5: =(0.00952*(('Part type'!J10)*10)+42.33704) -> 46.84952 | AG5: =(0.00952*(('Part type'!J11)*10)+42.33704) -> 46.83048 | AH5: =-(0.06747*(('Part type'!J8)*10)+4.96275) -> -37.82064 | AI5: =-(0.06747*(('Part type'!J9)*10)+4.96275) -> -37.07847 | AJ5: =-(0.06747*(('Part type'!J10)*10)+4.96275) -> -36.94353 | AK5: =-(0.06747*(('Part type'!J11)*10)+4.96275) -> -36.80859 | AL5: =-(0.05969*(('Part type'!J8)*10)+4.39079) -> -33.45982 | AM5: =-(0.05969*(('Part type'!J9)*10)+4.39079) -> -32.80323 | AN5: =-(0.05969*(('Part type'!J10)*10)+4.39079) -> -32.68385 | AO5: =-(0.05969*(('Part type'!J11)*10)+4.39079) -> -32.56447 | AP5: =-(0.08646*(('Part type'!J8)*10)+275.16974+('Part type'!C14)) -> -317.27576 | AQ5: =-(0.08646*(('Part type'!J9)*10)+275.16974+('Part type'!C14)) -> -316.3247 | AR5: =-(0.08646*(('Part type'!J10)*10)+275.16974+('Part type'!C14)) -> -316.15178 | AS5: =-(0.08646*(('Part type'!J11)*10)+275.16974+('Part type'!C14)) -> -315.97886 | AT5: =-(0.01351*(('Part type'!J8)*10)+39.90682) -> -46.48619 | AU5: =-(0.01351*(('Part type'!J9)*10)+39.90682) -> -46.33758 | AV5: =-(0.01351*(('Part type'!J10)*10)+39.90682) -> -46.31056 | AW5: =-(0.01351*(('Part type'!J11)*10)+39.90682) -> -46.28354 | AX5: =(0.07114*(('Part type'!J8)*10)+4.92748) -> 39.57266 | AY5: =(0.07114*(('Part type'!J9)*10)+4.92748) -> 38.79012 | AZ5: =(0.07114*(('Part type'!J10)*10)+4.92748) -> 38.64784 | BA5: =(0.07114*(('Part type'!J11)*10)+4.92748) -> 38.50556 | BB5: =-(0.05858*(('Part type'!J8)*10)+5) -> -33.52846 | BC5: =-(0.05858*(('Part type'!J9)*10)+5) -> -32.88408 | BD5: =-(0.05858*(('Part type'!J10)*10)+5) -> -32.76692 | BE5: =-(0.05858*(('Part type'!J11)*10)+5) -> -32.64976 | BF5: =(0.05858*(('Part type'!J8)*10)+5) -> 33.52846 | BG5: =(0.05858*(('Part type'!J9)*10)+5) -> 32.88408 | BH5: =(0.05858*(('Part type'!J10)*10)+5) -> 32.76692 | BI5: =(0.05858*(('Part type'!J11)*10)+5) -> 32.64976 | BJ5: 0 | BK5: 0 | BL5: 0 | BM5: 0 | BN5: 0 | BO5: 0 | BP5: 0 | BQ5: 0
A7: 129-122-03-211 | B7: =-((('Part type'!J8)*0.414214)-5) -> -15.172222 | C7: =-((('Part type'!J9)*0.414214)-5) -> -14.716586 | D7: =-((('Part type'!J10)*0.414214)-5) -> -14.633744 | E7: =-((('Part type'!J11)*0.414214)-5) -> -14.550901 | F7: =(0.08284*(('Part type'!J8)*10)+352+('Part type'!E13)) -> 392.34308 | G7: =(0.08284*(('Part type'!J9)*10)+352+('Part type'!E13)) -> 391.43184 | H7: =(0.08284*(('Part type'!J10)*10)+352+('Part type'!E13)) -> 391.26616 | I7: =(0.08284*(('Part type'!J11)*10)+352+('Part type'!E13)) -> 391.10048 | J7: =(0.05858*(('Part type'!J8)*10)+5) -> 33.52846 | K7: =(0.05858*(('Part type'!J9)*10)+5) -> 32.88408 | L7: =(0.05858*(('Part type'!J10)*10)+5) -> 32.76692 | M7: =(0.05858*(('Part type'!J11)*10)+5) -> 32.64976 | N7: =(0.08088*(('Part type'!J8)*10)+168.16505+('Part type'!C14)) -> 207.55361 | O7: =(0.08088*(('Part type'!J9)*10)+168.16505+('Part type'!C14)) -> 206.66393 | P7: =(0.08088*(('Part type'!J10)*10)+168.16505+('Part type'!C14)) -> 206.50217 | Q7: =(0.08088*(('Part type'!J11)*10)+168.16505+('Part type'!C14)) -> 206.34041 | R7: =(0.05766*(('Part type'!J8)*10)+5.33578) -> 33.4162 | S7: =(0.05766*(('Part type'!J9)*10)+5.33578) -> 32.78194 | T7: =(0.05766*(('Part type'!J10)*10)+5.33578) -> 32.66662 | U7: =(0.05766*(('Part type'!J11)*10)+5.33578) -> 32.5513 | V7: =-(0.05391*(('Part type'!J8)*10)+4.98871) -> -31.24288 | W7: =-(0.05391*(('Part type'!J9)*10)+4.98871) -> -30.64987 | X7: =-(0.05391*(('Part type'!J10)*10)+4.98871) -> -30.54205 | Y7: =-(0.05391*(('Part type'!J11)*10)+4.98871) -> -30.43423 | Z7: =-(0.08269*(('Part type'!J8)*10)+352.02257+('Part type'!C13)) -> -392.2926 | AA7: =-(0.08269*(('Part type'!J9)*10)+352.02257+('Part type'!C13)) -> -391.38301 | AB7: =-(0.08269*(('Part type'!J10)*10)+352.02257+('Part type'!C13)) -> -391.21763 | AC7: =-(0.08269*(('Part type'!J11)*10)+352.02257+('Part type'!C13)) -> -391.05225 | AD7: =(0.00556*(('Part type'!J8)*10)+23.69383) -> 26.40155 | AE7: =(0.00556*(('Part type'!J9)*10)+23.69383) -> 26.34039 | AF7: =(0.00556*(('Part type'!J10)*10)+23.69383) -> 26.32927 | AG7: =(0.00556*(('Part type'!J11)*10)+23.69383) -> 26.31815 | AH7: =-(0.06341*(('Part type'!J8)*10)+4.98871) -> -35.86938 | AI7: =-(0.06341*(('Part type'!J9)*10)+4.98871) -> -35.17187 | AJ7: =-(0.06341*(('Part type'!J10)*10)+4.98871) -> -35.04505 | AK7: =-(0.06341*(('Part type'!J11)*10)+4.98871) -> -34.91823 | AL7: =-(0.05929*(('Part type'!J8)*10)+4.66422) -> -33.53845 | AM7: =-(0.05929*(('Part type'!J9)*10)+4.66422) -> -32.88626 | AN7: =-(0.05929*(('Part type'!J10)*10)+4.66422) -> -32.76768 | AO7: =-(0.05929*(('Part type'!J11)*10)+4.66422) -> -32.6491 | AP7: =-(0.08482*(('Part type'!J8)*10)+192.53043+('Part type'!C14)) -> -233.83777 | AQ7: =-(0.08482*(('Part type'!J9)*10)+192.53043+('Part type'!C14)) -> -232.90475 | AR7: =-(0.08482*(('Part type'!J10)*10)+192.53043+('Part type'!C14)) -> -232.73511 | AS7: =-(0.08482*(('Part type'!J11)*10)+192.53043+('Part type'!C14)) -> -232.56547 | AT7: 0 | AU7: 0 | AV7: 0 | AW7: 0 | AX7: =(0.05858*(('Part type'!J8)*10)+5) -> 33.52846 | AY7: =(0.05858*(('Part type'!J9)*10)+5) -> 32.88408 | AZ7: =(0.05858*(('Part type'!J10)*10)+5) -> 32.76692 | BA7: =(0.05858*(('Part type'!J11)*10)+5) -> 32.64976 | BB7: =-(0.05858*(('Part type'!J8)*10)+5) -> -33.52846 | BC7: =-(0.05858*(('Part type'!J9)*10)+5) -> -32.88408 | BD7: =-(0.05858*(('Part type'!J10)*10)+5) -> -32.76692 | BE7: =-(0.05858*(('Part type'!J11)*10)+5) -> -32.64976 | BF7: =(0.05858*(('Part type'!J8)*10)+5) -> 33.52846 | BG7: =(0.05858*(('Part type'!J9)*10)+5) -> 32.88408 | BH7: =(0.05858*(('Part type'!J10)*10)+5) -> 32.76692 | BI7: =(0.05858*(('Part type'!J11)*10)+5) -> 32.64976 | BJ7: 0 | BK7: 0 | BL7: 0 | BM7: 0 | BN7: 0 | BO7: 0 | BP7: 0 | BQ7: 0
